{"stats": {"errors": 1, "failures": 0, "passes": 0, "skipped": 0, "encoding": "UTF-8", "total": 1}, "results": [{"classname": "python_getting_started_project.q01_read_data.tests.test_q01_read_data:TestRead_data", "name": "test_return_instance", "time": 0.0001773834228515625, "type": "error", "errtype": "builtins.FileNotFoundError", "message": "[Errno 2] No such file or directory: './data/'", "tb": "Traceback (most recent call last):\n  File \"/home/ubuntu/anaconda3/lib/python3.6/unittest/case.py\", line 59, in testPartExecutor\n    yield\n  File \"/home/ubuntu/anaconda3/lib/python3.6/unittest/case.py\", line 605, in run\n    testMethod()\n  File \"/home/gomsagar/Workspace/code/python_getting_started_project/q01_read_data/tests/test_q01_read_data.py\", line 9, in test_return_instance\n    result = read_data()\n  File \"/home/gomsagar/Workspace/code/python_getting_started_project/q01_read_data/build.py\", line 11, in read_data\n    os.chdir('./data/')\nFileNotFoundError: [Errno 2] No such file or directory: './data/'\n"}]}